<?xml version="1.0" encoding="utf-8"?>
<!-- This URDF was automatically created by SolidWorks to URDF Exporter! Originally created by Stephen Brawner (brawner@gmail.com) 
     Commit Version: 1.6.0-4-g7f85cfe  Build Version: 1.6.7995.38578
     For more information, please see http://wiki.ros.org/sw_urdf_exporter -->
<robot
  name="robot_esr_v2">
  <link
    name="base_link">
    <inertial>
      <origin
        xyz="-0.00195554448462078 -5.1194386791571E-06 0.0778454571324803"
        rpy="0 0 0" />
      <mass
        value="1.20329885641613" />
      <inertia
        ixx="0.00130731306384171"
        ixy="3.53640853384064E-06"
        ixz="4.78759424406522E-11"
        iyy="0.00296439184087798"
        iyz="2.52026599653312E-09"
        izz="0.00224592315752859" />
    </inertial>
    <visual>
      <origin
        xyz="0 0 0"
        rpy="0 0 0" />
      <geometry>
        <mesh
          filename="/home/dika/projects/AthleticRobot/robot/robot_esr_v2/meshes/base_link.STL" />
      </geometry>
      <material
        name="">
        <color
          rgba="0.792156862745098 0.819607843137255 0.933333333333333 1" />
      </material>
    </visual>
    <collision>
      <origin
        xyz="0 0 0"
        rpy="0 0 0" />
      <geometry>
        <mesh
          filename="/home/dika/projects/AthleticRobot/robot/robot_esr_v2/meshes/base_link.STL" />
      </geometry>
    </collision>
  </link>
  <link
    name="right_knee_yaw_2">
    <inertial>
      <origin
        xyz="2.39190602047135E-09 -0.0243423048956628 -0.00334373594226933"
        rpy="0 0 0" />
      <mass
        value="0.096159670070791" />
      <inertia
        ixx="0.000128656949644948"
        ixy="-4.79620647782242E-13"
        ixz="2.35777135909615E-09"
        iyy="0.000132522868391436"
        iyz="2.5450929015229E-07"
        izz="5.12800218306316E-05" />
    </inertial>
    <visual>
      <origin
        xyz="0 0 0"
        rpy="0 0 0" />
      <geometry>
        <mesh
          filename="/home/dika/projects/AthleticRobot/robot/robot_esr_v2/meshes/right_knee_yaw_2.STL" />
      </geometry>
      <material
        name="">
        <color
          rgba="0.792156862745098 0.819607843137255 0.933333333333333 1" />
      </material>
    </visual>
    <collision>
      <origin
        xyz="0 0 0"
        rpy="0 0 0" />
      <geometry>
        <mesh
          filename="/home/dika/projects/AthleticRobot/robot/robot_esr_v2/meshes/right_knee_yaw_2.STL" />
      </geometry>
    </collision>
  </link>
  <joint
    name="right_knee_yaw_2"
    type="continuous">
    <origin
      xyz="-0.093 0.012 -0.012"
      rpy="1.5707963267949 0 0" />
    <parent
      link="base_link" />
    <child
      link="right_knee_yaw_2" />
    <axis
      xyz="0 -1 0" />
  </joint>
  <link
    name="right_knee_roll_2">
    <inertial>
      <origin
        xyz="0.000202501643025876 2.75407904815061E-10 -0.028607130429822"
        rpy="0 0 0" />
      <mass
        value="0.368139820135188" />
      <inertia
        ixx="0.000487383753640405"
        ixy="2.22939199806448E-12"
        ixz="4.1813199928851E-06"
        iyy="0.000468934971003584"
        iyz="4.38250512477698E-12"
        izz="0.000167108497311385" />
    </inertial>
    <visual>
      <origin
        xyz="0 0 0"
        rpy="0 0 0" />
      <geometry>
        <mesh
          filename="/home/dika/projects/AthleticRobot/robot/robot_esr_v2/meshes/right_knee_roll_2.STL" />
      </geometry>
      <material
        name="">
        <color
          rgba="0.792156862745098 0.819607843137255 0.933333333333333 1" />
      </material>
    </visual>
    <collision>
      <origin
        xyz="0 0 0"
        rpy="0 0 0" />
      <geometry>
        <mesh
          filename="/home/dika/projects/AthleticRobot/robot/robot_esr_v2/meshes/right_knee_roll_2.STL" />
      </geometry>
    </collision>
  </link>
  <joint
    name="right_knee_roll_2"
    type="revolute">
    <origin
      xyz="0 -0.075 0.033"
      rpy="0 0 0" />
    <parent
      link="right_knee_yaw_2" />
    <child
      link="right_knee_roll_2" />
    <axis
      xyz="0 0 -1" />
    <limit
      lower="-1.57"
      upper="1.57"
      effort="0"
      velocity="0" />
  </joint>
  <link
    name="right_knee_pitch_2">
    <inertial>
      <origin
        xyz="-0.0705682481727586 -0.171821064771947 -0.0114422794800575"
        rpy="0 0 0" />
      <mass
        value="1.04919994241207" />
      <inertia
        ixx="0.00203551826198784"
        ixy="-6.46257017899787E-06"
        ixz="1.83437475857554E-06"
        iyy="0.00109535082544024"
        iyz="-0.000164908841445616"
        izz="0.00241077491941216" />
    </inertial>
    <visual>
      <origin
        xyz="0 0 0"
        rpy="0 0 0" />
      <geometry>
        <mesh
          filename="/home/dika/projects/AthleticRobot/robot/robot_esr_v2/meshes/right_knee_pitch_2.STL" />
      </geometry>
      <material
        name="">
        <color
          rgba="0.792156862745098 0.819607843137255 0.933333333333333 1" />
      </material>
    </visual>
    <collision>
      <origin
        xyz="0 0 0"
        rpy="0 0 0" />
      <geometry>
        <mesh
          filename="/home/dika/projects/AthleticRobot/robot/robot_esr_v2/meshes/right_knee_pitch_2.STL" />
      </geometry>
    </collision>
  </link>
  <joint
    name="right_knee_pitch_2"
    type="revolute">
    <origin
      xyz="0.0449 0 -0.021"
      rpy="0 0 0" />
    <parent
      link="right_knee_roll_2" />
    <child
      link="right_knee_pitch_2" />
    <axis
      xyz="1 0 0" />
    <limit
      lower="-1.57"
      upper="1.57"
      effort="0"
      velocity="0" />
  </joint>
  <link
    name="right_knee_pitch_4">
    <inertial>
      <origin
        xyz="-0.0645776090677919 -0.173677062141295 0.0232634636154186"
        rpy="0 0 0" />
      <mass
        value="0.835928343617776" />
      <inertia
        ixx="0.00137391244248698"
        ixy="1.75764496479534E-05"
        ixz="-6.94594844151765E-07"
        iyy="0.000799355378882546"
        iyz="-6.19621632353491E-05"
        izz="0.00156571451413064" />
    </inertial>
    <visual>
      <origin
        xyz="0 0 0"
        rpy="0 0 0" />
      <geometry>
        <mesh
          filename="/home/dika/projects/AthleticRobot/robot/robot_esr_v2/meshes/right_knee_pitch_4.STL" />
      </geometry>
      <material
        name="">
        <color
          rgba="0.749019607843137 0.749019607843137 0.749019607843137 1" />
      </material>
    </visual>
    <collision>
      <origin
        xyz="0 0 0"
        rpy="0 0 0" />
      <geometry>
        <mesh
          filename="/home/dika/projects/AthleticRobot/robot/robot_esr_v2/meshes/right_knee_pitch_4.STL" />
      </geometry>
    </collision>
  </link>
  <joint
    name="right_knee_pitch_4"
    type="revolute">
    <origin
      xyz="-0.0054 -0.2983565686105 -0.0313585389803"
      rpy="0 0 0" />
    <parent
      link="right_knee_pitch_2" />
    <child
      link="right_knee_pitch_4" />
    <axis
      xyz="-1 0 0" />
    <limit
      lower="-1.57"
      upper="1.57"
      effort="0"
      velocity="0" />
  </joint>
  <link
    name="right_knee_pitch_6">
    <inertial>
      <origin
        xyz="-0.0435940717346724 0.00031222360648453 -0.00595757596241889"
        rpy="0 0 0" />
      <mass
        value="0.370446086229337" />
      <inertia
        ixx="0.000489846606383234"
        ixy="-2.18831170155361E-07"
        ixz="4.17558971578793E-06"
        iyy="0.000468492122364731"
        iyz="1.58643557100187E-05"
        izz="0.000166613714621281" />
    </inertial>
    <visual>
      <origin
        xyz="0 0 0"
        rpy="0 0 0" />
      <geometry>
        <mesh
          filename="/home/dika/projects/AthleticRobot/robot/robot_esr_v2/meshes/right_knee_pitch_6.STL" />
      </geometry>
      <material
        name="">
        <color
          rgba="0.792156862745098 0.819607843137255 0.933333333333333 1" />
      </material>
    </visual>
    <collision>
      <origin
        xyz="0 0 0"
        rpy="0 0 0" />
      <geometry>
        <mesh
          filename="/home/dika/projects/AthleticRobot/robot/robot_esr_v2/meshes/right_knee_pitch_6.STL" />
      </geometry>
    </collision>
  </link>
  <joint
    name="right_knee_pitch_6"
    type="revolute">
    <origin
      xyz="0.0054 -0.299588860426366 0.0157007868728399"
      rpy="0 0 0" />
    <parent
      link="right_knee_pitch_4" />
    <child
      link="right_knee_pitch_6" />
    <axis
      xyz="1 0 0" />
    <limit
      lower="-1.57"
      upper="1.57"
      effort="0"
      velocity="0" />
  </joint>
  <link
    name="right_knee_roll_6">
    <inertial>
      <origin
        xyz="-0.00886091150390085 -0.0953365716937131 -0.0276213346605024"
        rpy="0 0 0" />
      <mass
        value="0.576558644743931" />
      <inertia
        ixx="0.00179506509811955"
        ixy="-7.39343202354004E-06"
        ixz="-3.87438816394618E-07"
        iyy="0.00250162707886782"
        iyz="8.91468136657886E-05"
        izz="0.000798690715389373" />
    </inertial>
    <visual>
      <origin
        xyz="0 0 0"
        rpy="0 0 0" />
      <geometry>
        <mesh
          filename="/home/dika/projects/AthleticRobot/robot/robot_esr_v2/meshes/right_knee_roll_6.STL" />
      </geometry>
      <material
        name="">
        <color
          rgba="0.792156862745098 0.819607843137255 0.933333333333333 1" />
      </material>
    </visual>
    <collision>
      <origin
        xyz="0 0 0"
        rpy="0 0 0" />
      <geometry>
        <mesh
          filename="/home/dika/projects/AthleticRobot/robot/robot_esr_v2/meshes/right_knee_roll_6.STL" />
      </geometry>
    </collision>
  </link>
  <joint
    name="right_knee_roll_6"
    type="revolute">
    <origin
      xyz="-0.0449 -0.00109905508110331 0.0209712202298987"
      rpy="0 0 0" />
    <parent
      link="right_knee_pitch_6" />
    <child
      link="right_knee_roll_6" />
    <axis
      xyz="0 0.0523359562429437 -0.998629534754574" />
    <limit
      lower="-1.57"
      upper="1.57"
      effort="0"
      velocity="0" />
  </joint>
  <link
    name="left_knee_yaw_1">
    <inertial>
      <origin
        xyz="2.39190600659356E-09 -0.0243423048956628 -0.00334373594226932"
        rpy="0 0 0" />
      <mass
        value="0.096159670070791" />
      <inertia
        ixx="0.000128656949644948"
        ixy="-4.79620646314158E-13"
        ixz="2.35777135910133E-09"
        iyy="0.000132522868391436"
        iyz="2.54509290152293E-07"
        izz="5.12800218306316E-05" />
    </inertial>
    <visual>
      <origin
        xyz="0 0 0"
        rpy="0 0 0" />
      <geometry>
        <mesh
          filename="/home/dika/projects/AthleticRobot/robot/robot_esr_v2/meshes/left_knee_yaw_1.STL" />
      </geometry>
      <material
        name="">
        <color
          rgba="0.792156862745098 0.819607843137255 0.933333333333333 1" />
      </material>
    </visual>
    <collision>
      <origin
        xyz="0 0 0"
        rpy="0 0 0" />
      <geometry>
        <mesh
          filename="/home/dika/projects/AthleticRobot/robot/robot_esr_v2/meshes/left_knee_yaw_1.STL" />
      </geometry>
    </collision>
  </link>
  <joint
    name="left_knee_yaw_1"
    type="continuous">
    <origin
      xyz="0.093 0.012 -0.012"
      rpy="1.5707963267949 0 0" />
    <parent
      link="base_link" />
    <child
      link="left_knee_yaw_1" />
    <axis
      xyz="0 -1 0" />
  </joint>
  <link
    name="left_knee_roll_1">
    <inertial>
      <origin
        xyz="-0.00020250164302589 -2.75407904815061E-10 -0.028607130429822"
        rpy="0 0 0" />
      <mass
        value="0.368139820135188" />
      <inertia
        ixx="0.000487383753640405"
        ixy="2.22939199863096E-12"
        ixz="-4.1813199928851E-06"
        iyy="0.000468934971003584"
        iyz="-4.38250513328121E-12"
        izz="0.000167108497311385" />
    </inertial>
    <visual>
      <origin
        xyz="0 0 0"
        rpy="0 0 0" />
      <geometry>
        <mesh
          filename="/home/dika/projects/AthleticRobot/robot/robot_esr_v2/meshes/left_knee_roll_1.STL" />
      </geometry>
      <material
        name="">
        <color
          rgba="0.792156862745098 0.819607843137255 0.933333333333333 1" />
      </material>
    </visual>
    <collision>
      <origin
        xyz="0 0 0"
        rpy="0 0 0" />
      <geometry>
        <mesh
          filename="/home/dika/projects/AthleticRobot/robot/robot_esr_v2/meshes/left_knee_roll_1.STL" />
      </geometry>
    </collision>
  </link>
  <joint
    name="left_knee_roll_1"
    type="revolute">
    <origin
      xyz="0 -0.075 0.033"
      rpy="0 0 0" />
    <parent
      link="left_knee_yaw_1" />
    <child
      link="left_knee_roll_1" />
    <axis
      xyz="0 0 -1" />
    <limit
      lower="-1.57"
      upper="1.57"
      effort="0"
      velocity="0" />
  </joint>
  <link
    name="left_knee_pitch_1">
    <inertial>
      <origin
        xyz="0.0705059252490257 -0.171821064713912 -0.0114600393459196"
        rpy="0 0 0" />
      <mass
        value="1.04919994241207" />
      <inertia
        ixx="0.00203551826198784"
        ixy="6.76864618420667E-06"
        ixz="-1.16252733593949E-06"
        iyy="0.00109535082245673"
        iyz="-0.000165858004182792"
        izz="0.00241077492239567" />
    </inertial>
    <visual>
      <origin
        xyz="0 0 0"
        rpy="0 0 0" />
      <geometry>
        <mesh
          filename="/home/dika/projects/AthleticRobot/robot/robot_esr_v2/meshes/left_knee_pitch_1.STL" />
      </geometry>
      <material
        name="">
        <color
          rgba="0.792156862745098 0.819607843137255 0.933333333333333 1" />
      </material>
    </visual>
    <collision>
      <origin
        xyz="0 0 0"
        rpy="0 0 0" />
      <geometry>
        <mesh
          filename="/home/dika/projects/AthleticRobot/robot/robot_esr_v2/meshes/left_knee_pitch_1.STL" />
      </geometry>
    </collision>
  </link>
  <joint
    name="left_knee_pitch_1"
    type="revolute">
    <origin
      xyz="-0.0449 0 -0.021"
      rpy="0 0 0" />
    <parent
      link="left_knee_roll_1" />
    <child
      link="left_knee_pitch_1" />
    <axis
      xyz="-1 0 0" />
    <limit
      lower="-1.57"
      upper="1.57"
      effort="0"
      velocity="0" />
  </joint>
  <link
    name="left_knee_pitch_3">
    <inertial>
      <origin
        xyz="0.0255393342693625 -0.160882246126205 0.0241162469494275"
        rpy="0 0 0" />
      <mass
        value="0.585704426632643" />
      <inertia
        ixx="0.00126020115115167"
        ixy="-1.7895630813641E-05"
        ixz="2.45183052251936E-06"
        iyy="0.000572553520859722"
        iyz="-6.41071068231679E-05"
        izz="0.00133802673415994" />
    </inertial>
    <visual>
      <origin
        xyz="0 0 0"
        rpy="0 0 0" />
      <geometry>
        <mesh
          filename="/home/dika/projects/AthleticRobot/robot/robot_esr_v2/meshes/left_knee_pitch_3.STL" />
      </geometry>
      <material
        name="">
        <color
          rgba="0.749019607843137 0.749019607843137 0.749019607843137 1" />
      </material>
    </visual>
    <collision>
      <origin
        xyz="0 0 0"
        rpy="0 0 0" />
      <geometry>
        <mesh
          filename="/home/dika/projects/AthleticRobot/robot/robot_esr_v2/meshes/left_knee_pitch_3.STL" />
      </geometry>
    </collision>
  </link>
  <joint
    name="left_knee_pitch_3"
    type="revolute">
    <origin
      xyz="0.0449 -0.2983565686105 -0.0313585389803004"
      rpy="0 0 0" />
    <parent
      link="left_knee_pitch_1" />
    <child
      link="left_knee_pitch_3" />
    <axis
      xyz="1 0 0" />
    <limit
      lower="-1.57"
      upper="1.57"
      effort="0"
      velocity="0" />
  </joint>
  <link
    name="left_knee_pitch_5">
    <inertial>
      <origin
        xyz="0.0443712813740971 0.000328520446688296 -0.00608213103936753"
        rpy="0 0 0" />
      <mass
        value="0.362828850117247" />
      <inertia
        ixx="0.000487503415167199"
        ixy="2.25523673518831E-07"
        ixz="-4.17523361478075E-06"
        iyy="0.000467244629757143"
        iyz="1.634780428137E-05"
        izz="0.000165469414154828" />
    </inertial>
    <visual>
      <origin
        xyz="0 0 0"
        rpy="0 0 0" />
      <geometry>
        <mesh
          filename="/home/dika/projects/AthleticRobot/robot/robot_esr_v2/meshes/left_knee_pitch_5.STL" />
      </geometry>
      <material
        name="">
        <color
          rgba="0.792156862745098 0.819607843137255 0.933333333333333 1" />
      </material>
    </visual>
    <collision>
      <origin
        xyz="0 0 0"
        rpy="0 0 0" />
      <geometry>
        <mesh
          filename="/home/dika/projects/AthleticRobot/robot/robot_esr_v2/meshes/left_knee_pitch_5.STL" />
      </geometry>
    </collision>
  </link>
  <joint
    name="left_knee_pitch_5"
    type="revolute">
    <origin
      xyz="-0.0449 -0.299613625160821 0.0152208941257087"
      rpy="0 0 0" />
    <parent
      link="left_knee_pitch_3" />
    <child
      link="left_knee_pitch_5" />
    <axis
      xyz="-1 0 0" />
    <limit
      lower="-1.57"
      upper="1.57"
      effort="0"
      velocity="0" />
  </joint>
  <link
    name="left_knee_roll_5">
    <inertial>
      <origin
        xyz="0.0114436397158781 -0.0952922063529219 -0.0277740065386727"
        rpy="0 0 0" />
      <mass
        value="0.576558644730299" />
      <inertia
        ixx="0.00179506509809567"
        ixy="7.38465957071978E-06"
        ixz="3.98910172076268E-07"
        iyy="0.00250133712456066"
        iyz="9.18740659825815E-05"
        izz="0.000798980669669122" />
    </inertial>
    <visual>
      <origin
        xyz="0 0 0"
        rpy="0 0 0" />
      <geometry>
        <mesh
          filename="/home/dika/projects/AthleticRobot/robot/robot_esr_v2/meshes/left_knee_roll_5.STL" />
      </geometry>
      <material
        name="">
        <color
          rgba="0.792156862745098 0.819607843137255 0.933333333333333 1" />
      </material>
    </visual>
    <collision>
      <origin
        xyz="0 0 0"
        rpy="0 0 0" />
      <geometry>
        <mesh
          filename="/home/dika/projects/AthleticRobot/robot/robot_esr_v2/meshes/left_knee_roll_5.STL" />
      </geometry>
    </collision>
  </link>
  <joint
    name="left_knee_roll_5"
    type="revolute">
    <origin
      xyz="0.0449 -0.00113264475358943 0.0209694328932467"
      rpy="0 0 0" />
    <parent
      link="left_knee_pitch_5" />
    <child
      link="left_knee_roll_5" />
    <axis
      xyz="0 0.0539354644565479 -0.998544423485433" />
    <limit
      lower="-1.57"
      upper="1.57"
      effort="0"
      velocity="0" />
  </joint>
  <link
    name="body_pitch">
    <inertial>
      <origin
        xyz="0.0331532032290532 0.03679618621314 1.65340831304039E-18"
        rpy="0 0 0" />
      <mass
        value="0.103869014537954" />
      <inertia
        ixx="8.15711773514188E-05"
        ixy="-2.0641659849425E-19"
        ixz="1.89744782077141E-20"
        iyy="0.00028158564415382"
        iyz="8.77369317441642E-21"
        izz="0.000275198587076672" />
    </inertial>
    <visual>
      <origin
        xyz="0 0 0"
        rpy="0 0 0" />
      <geometry>
        <mesh
          filename="/home/dika/projects/AthleticRobot/robot/robot_esr_v2/meshes/body_pitch.STL" />
      </geometry>
      <material
        name="">
        <color
          rgba="0.996078431372549 0.996078431372549 1 1" />
      </material>
    </visual>
    <collision>
      <origin
        xyz="0 0 0"
        rpy="0 0 0" />
      <geometry>
        <mesh
          filename="/home/dika/projects/AthleticRobot/robot/robot_esr_v2/meshes/body_pitch.STL" />
      </geometry>
    </collision>
  </link>
  <joint
    name="body_pitch"
    type="revolute">
    <origin
      xyz="-0.026672763878276 -0.000154472308284991 0.155"
      rpy="1.5707963267949 0 0" />
    <parent
      link="base_link" />
    <child
      link="body_pitch" />
    <axis
      xyz="1 0 0" />
    <limit
      lower="-1.57"
      upper="1.57"
      effort="0"
      velocity="0" />
  </joint>
  <link
    name="body_yaw">
    <inertial>
      <origin
        xyz="6.41386045515302E-05 0.149604906423815 0.00111334035407071"
        rpy="0 0 0" />
      <mass
        value="1.32362172705301" />
      <inertia
        ixx="0.00153326959317075"
        ixy="-2.99746241922474E-06"
        ixz="7.78354855322143E-08"
        iyy="0.00192110179117074"
        iyz="-3.73436079562119E-07"
        izz="0.00292594754595678" />
    </inertial>
    <visual>
      <origin
        xyz="0 0 0"
        rpy="0 0 0" />
      <geometry>
        <mesh
          filename="/home/dika/projects/AthleticRobot/robot/robot_esr_v2/meshes/body_yaw.STL" />
      </geometry>
      <material
        name="">
        <color
          rgba="0.792156862745098 0.819607843137255 0.933333333333333 1" />
      </material>
    </visual>
    <collision>
      <origin
        xyz="0 0 0"
        rpy="0 0 0" />
      <geometry>
        <mesh
          filename="/home/dika/projects/AthleticRobot/robot/robot_esr_v2/meshes/body_yaw.STL" />
      </geometry>
    </collision>
  </link>
  <joint
    name="body_yaw"
    type="continuous">
    <origin
      xyz="0.026672999999998 0.065500000000001 0"
      rpy="0 0 0" />
    <parent
      link="body_pitch" />
    <child
      link="body_yaw" />
    <axis
      xyz="0 1 0" />
  </joint>
  <link
    name="right_arm_pitch_2">
    <inertial>
      <origin
        xyz="-0.062355023573555 -0.00944958671211305 -0.00514148471440848"
        rpy="0 0 0" />
      <mass
        value="0.0708497719733451" />
      <inertia
        ixx="6.84919892845484E-05"
        ixy="-4.90871002711246E-06"
        ixz="-2.53787320186342E-08"
        iyy="5.54509556778551E-05"
        iyz="2.1928136683237E-08"
        izz="4.70546086781182E-05" />
    </inertial>
    <visual>
      <origin
        xyz="0 0 0"
        rpy="0 0 0" />
      <geometry>
        <mesh
          filename="/home/dika/projects/AthleticRobot/robot/robot_esr_v2/meshes/right_arm_pitch_2.STL" />
      </geometry>
      <material
        name="">
        <color
          rgba="0.792156862745098 0.819607843137255 0.933333333333333 1" />
      </material>
    </visual>
    <collision>
      <origin
        xyz="0 0 0"
        rpy="0 0 0" />
      <geometry>
        <mesh
          filename="/home/dika/projects/AthleticRobot/robot/robot_esr_v2/meshes/right_arm_pitch_2.STL" />
      </geometry>
    </collision>
  </link>
  <joint
    name="right_arm_pitch_2"
    type="revolute">
    <origin
      xyz="-0.116 0.1865 0"
      rpy="0 0 0" />
    <parent
      link="body_yaw" />
    <child
      link="right_arm_pitch_2" />
    <axis
      xyz="1 0 0" />
    <limit
      lower="-3.14"
      upper="3.14"
      effort="0"
      velocity="0" />
  </joint>
  <link
    name="right_arm_roll_2">
    <inertial>
      <origin
        xyz="-0.000143114439140196 -0.0593378709159931 -0.0219648695125198"
        rpy="0 0 0" />
      <mass
        value="0.63999361019222" />
      <inertia
        ixx="0.000699632566014424"
        ixy="3.51428410162046E-06"
        ixz="5.73943656128552E-11"
        iyy="0.000502483362631469"
        iyz="-3.51429064120545E-06"
        izz="0.000525405260146243" />
    </inertial>
    <visual>
      <origin
        xyz="0 0 0"
        rpy="0 0 0" />
      <geometry>
        <mesh
          filename="/home/dika/projects/AthleticRobot/robot/robot_esr_v2/meshes/right_arm_roll_2.STL" />
      </geometry>
      <material
        name="">
        <color
          rgba="0.792156862745098 0.819607843137255 0.933333333333333 1" />
      </material>
    </visual>
    <collision>
      <origin
        xyz="0 0 0"
        rpy="0 0 0" />
      <geometry>
        <mesh
          filename="/home/dika/projects/AthleticRobot/robot/robot_esr_v2/meshes/right_arm_roll_2.STL" />
      </geometry>
    </collision>
  </link>
  <joint
    name="right_arm_roll_2"
    type="revolute">
    <origin
      xyz="-0.0960000000000002 -0.039 0.027"
      rpy="0 0 0" />
    <parent
      link="right_arm_pitch_2" />
    <child
      link="right_arm_roll_2" />
    <axis
      xyz="0 0 -1" />
    <limit
      lower="-3.14"
      upper="3.14"
      effort="0"
      velocity="0" />
  </joint>
  <link
    name="right_arm_yaw_2">
    <inertial>
      <origin
        xyz="-0.00314972637197275 -0.0551148453865819 0.000247660053044167"
        rpy="0 0 0" />
      <mass
        value="0.0464659333613767" />
      <inertia
        ixx="2.48384911458059E-05"
        ixy="-4.10901477652728E-08"
        ixz="4.78865636672604E-08"
        iyy="5.17570457355114E-05"
        iyz="1.24795287733788E-06"
        izz="4.24958513780217E-05" />
    </inertial>
    <visual>
      <origin
        xyz="0 0 0"
        rpy="0 0 0" />
      <geometry>
        <mesh
          filename="/home/dika/projects/AthleticRobot/robot/robot_esr_v2/meshes/right_arm_yaw_2.STL" />
      </geometry>
      <material
        name="">
        <color
          rgba="0.792156862745098 0.819607843137255 0.933333333333333 1" />
      </material>
    </visual>
    <collision>
      <origin
        xyz="0 0 0"
        rpy="0 0 0" />
      <geometry>
        <mesh
          filename="/home/dika/projects/AthleticRobot/robot/robot_esr_v2/meshes/right_arm_yaw_2.STL" />
      </geometry>
    </collision>
  </link>
  <joint
    name="right_arm_yaw_2"
    type="revolute">
    <origin
      xyz="-4.99999999987455E-05 -0.127 -0.02355"
      rpy="0 0 0" />
    <parent
      link="right_arm_roll_2" />
    <child
      link="right_arm_yaw_2" />
    <axis
      xyz="0 1 0" />
    <limit
      lower="-3.14"
      upper="3.14"
      effort="0"
      velocity="0" />
  </joint>
  <link
    name="right_arm_pitch_4">
    <inertial>
      <origin
        xyz="-0.0192399131176968 -0.0121662464498119 0.0369902124716069"
        rpy="0 0 0" />
      <mass
        value="0.484792170050265" />
      <inertia
        ixx="0.00027422962486239"
        ixy="2.48497300759922E-06"
        ixz="-3.02651534251846E-06"
        iyy="0.000484217295409479"
        iyz="-3.33398964424861E-06"
        izz="0.000424604377814633" />
    </inertial>
    <visual>
      <origin
        xyz="0 0 0"
        rpy="0 0 0" />
      <geometry>
        <mesh
          filename="/home/dika/projects/AthleticRobot/robot/robot_esr_v2/meshes/right_arm_pitch_4.STL" />
      </geometry>
      <material
        name="">
        <color
          rgba="0.792156862745098 0.819607843137255 0.933333333333333 1" />
      </material>
    </visual>
    <collision>
      <origin
        xyz="0 0 0"
        rpy="0 0 0" />
      <geometry>
        <mesh
          filename="/home/dika/projects/AthleticRobot/robot/robot_esr_v2/meshes/right_arm_pitch_4.STL" />
      </geometry>
    </collision>
  </link>
  <joint
    name="right_arm_pitch_4"
    type="revolute">
    <origin
      xyz="0.0210000000000009 -0.0899999999999988 0.03"
      rpy="0 0 0" />
    <parent
      link="right_arm_yaw_2" />
    <child
      link="right_arm_pitch_4" />
    <axis
      xyz="-1 0 0" />
    <limit
      lower="-1.57"
      upper="1.57"
      effort="0"
      velocity="0" />
  </joint>
  <link
    name="right_arm_pitch_6">
    <inertial>
      <origin
        xyz="-0.0487057773064401 -4.41559674796421E-08 0.0669453824285969"
        rpy="0 0 0" />
      <mass
        value="0.156307860481728" />
      <inertia
        ixx="5.38094237217675E-05"
        ixy="-3.64171257763483E-10"
        ixz="3.79663225663823E-06"
        iyy="0.000130633825677109"
        iyz="2.36477845053205E-11"
        izz="0.000101201355386492" />
    </inertial>
    <visual>
      <origin
        xyz="0 0 0"
        rpy="0 0 0" />
      <geometry>
        <mesh
          filename="/home/dika/projects/AthleticRobot/robot/robot_esr_v2/meshes/right_arm_pitch_6.STL" />
      </geometry>
      <material
        name="">
        <color
          rgba="0.894117647058823 0.894117647058823 0.894117647058823 1" />
      </material>
    </visual>
    <collision>
      <origin
        xyz="0 0 0"
        rpy="0 0 0" />
      <geometry>
        <mesh
          filename="/home/dika/projects/AthleticRobot/robot/robot_esr_v2/meshes/right_arm_pitch_6.STL" />
      </geometry>
    </collision>
  </link>
  <joint
    name="right_arm_pitch_6"
    type="revolute">
    <origin
      xyz="0.0300000000000011 -0.0300000000000048 0.107999999999998"
      rpy="0 0 0" />
    <parent
      link="right_arm_pitch_4" />
    <child
      link="right_arm_pitch_6" />
    <axis
      xyz="-1 0 0" />
    <limit
      lower="-1.57"
      upper="1.57"
      effort="0"
      velocity="0" />
  </joint>
  <link
    name="right_thumb_2">
    <inertial>
      <origin
        xyz="0.0113980157039383 0.00249998941206471 -0.00145796984257533"
        rpy="0 0 0" />
      <mass
        value="0.00454612592466201" />
      <inertia
        ixx="2.00745074820098E-07"
        ixy="4.76090321385866E-13"
        ixz="-1.50629419637734E-08"
        iyy="1.84541928008056E-07"
        iyz="2.14307776047516E-12"
        izz="2.07603348807424E-07" />
    </inertial>
    <visual>
      <origin
        xyz="0 0 0"
        rpy="0 0 0" />
      <geometry>
        <mesh
          filename="/home/dika/projects/AthleticRobot/robot/robot_esr_v2/meshes/right_thumb_2.STL" />
      </geometry>
      <material
        name="">
        <color
          rgba="0.749019607843137 0.749019607843137 0.749019607843137 1" />
      </material>
    </visual>
    <collision>
      <origin
        xyz="0 0 0"
        rpy="0 0 0" />
      <geometry>
        <mesh
          filename="/home/dika/projects/AthleticRobot/robot/robot_esr_v2/meshes/right_thumb_2.STL" />
      </geometry>
    </collision>
  </link>
  <joint
    name="right_thumb_2"
    type="revolute">
    <origin
      xyz="-0.110240030268082 -0.000182112936903053 0.0862281433963395"
      rpy="1.5707963267949 -0.463647609000797 -3.14159265358979" />
    <parent
      link="right_arm_pitch_6" />
    <child
      link="right_thumb_2" />
    <axis
      xyz="0 -1 0" />
    <limit
      lower="-1.57"
      upper="1.57"
      effort="0"
      velocity="0" />
  </joint>
  <link
    name="right_thumb_4">
    <inertial>
      <origin
        xyz="0.013958778160782 0.00249993828851755 -0.000754952657870928"
        rpy="0 0 0" />
      <mass
        value="0.00673411803056322" />
      <inertia
        ixx="2.83819391528249E-07"
        ixy="6.51704385668881E-12"
        ixz="-5.25786245489188E-08"
        iyy="5.0642235965004E-07"
        iyz="-3.38797188657897E-12"
        izz="5.30110015045949E-07" />
    </inertial>
    <visual>
      <origin
        xyz="0 0 0"
        rpy="0 0 0" />
      <geometry>
        <mesh
          filename="/home/dika/projects/AthleticRobot/robot/robot_esr_v2/meshes/right_thumb_4.STL" />
      </geometry>
      <material
        name="">
        <color
          rgba="0.749019607843137 0.749019607843137 0.749019607843137 1" />
      </material>
    </visual>
    <collision>
      <origin
        xyz="0 0 0"
        rpy="0 0 0" />
      <geometry>
        <mesh
          filename="/home/dika/projects/AthleticRobot/robot/robot_esr_v2/meshes/right_thumb_4.STL" />
      </geometry>
    </collision>
  </link>
  <joint
    name="right_thumb_4"
    type="revolute">
    <origin
      xyz="0.024 0 0"
      rpy="0 0 0" />
    <parent
      link="right_thumb_2" />
    <child
      link="right_thumb_4" />
    <axis
      xyz="0 -1 0" />
    <limit
      lower="-1.57"
      upper="1.57"
      effort="0"
      velocity="0" />
  </joint>
  <link
    name="right_finger_2">
    <inertial>
      <origin
        xyz="-0.0210004532113474 0.00399960516520242 0.00133246837422961"
        rpy="0 0 0" />
      <mass
        value="0.0353312587492228" />
      <inertia
        ixx="3.41570603712295E-06"
        ixy="6.1464644054689E-12"
        ixz="-2.22186015853765E-07"
        iyy="3.64845458130878E-06"
        iyz="2.16360534220781E-11"
        izz="5.5176988019767E-06" />
    </inertial>
    <visual>
      <origin
        xyz="0 0 0"
        rpy="0 0 0" />
      <geometry>
        <mesh
          filename="/home/dika/projects/AthleticRobot/robot/robot_esr_v2/meshes/right_finger_2.STL" />
      </geometry>
      <material
        name="">
        <color
          rgba="0.749019607843137 0.749019607843137 0.749019607843137 1" />
      </material>
    </visual>
    <collision>
      <origin
        xyz="0 0 0"
        rpy="0 0 0" />
      <geometry>
        <mesh
          filename="/home/dika/projects/AthleticRobot/robot/robot_esr_v2/meshes/right_finger_2.STL" />
      </geometry>
    </collision>
  </link>
  <joint
    name="right_finger_2"
    type="revolute">
    <origin
      xyz="-0.0495000000000036 0 0.111248350851721"
      rpy="1.57079632679489 1.5707963267949 0" />
    <parent
      link="right_arm_pitch_6" />
    <child
      link="right_finger_2" />
    <axis
      xyz="0 -1 0" />
    <limit
      lower="-1.57"
      upper="1.57"
      effort="0"
      velocity="0" />
  </joint>
  <link
    name="right_finger_4">
    <inertial>
      <origin
        xyz="0.024705968156843 -0.00391806732972669 0.000316275468702165"
        rpy="0 0 0" />
      <mass
        value="0.0496221300364541" />
      <inertia
        ixx="4.81577845078241E-06"
        ixy="-8.63051944714964E-12"
        ixz="2.88351448144049E-07"
        iyy="7.89374502164341E-06"
        iyz="3.29237520175746E-11"
        izz="1.04187874067314E-05" />
    </inertial>
    <visual>
      <origin
        xyz="0 0 0"
        rpy="0 0 0" />
      <geometry>
        <mesh
          filename="/home/dika/projects/AthleticRobot/robot/robot_esr_v2/meshes/right_finger_4.STL" />
      </geometry>
      <material
        name="">
        <color
          rgba="0.749019607843137 0.749019607843137 0.749019607843137 1" />
      </material>
    </visual>
    <collision>
      <origin
        xyz="0 0 0"
        rpy="0 0 0" />
      <geometry>
        <mesh
          filename="/home/dika/projects/AthleticRobot/robot/robot_esr_v2/meshes/right_finger_4.STL" />
      </geometry>
    </collision>
  </link>
  <joint
    name="right_finger_4"
    type="revolute">
    <origin
      xyz="-0.0395000000000001 0 0"
      rpy="0 0 3.14159265358979" />
    <parent
      link="right_finger_2" />
    <child
      link="right_finger_4" />
    <axis
      xyz="0 1 0" />
    <limit
      lower="-1.57"
      upper="1.57"
      effort="0"
      velocity="0" />
  </joint>
  <link
    name="left_arm_pitch_1">
    <inertial>
      <origin
        xyz="0.0611472845684249 -0.00838882976429184 -0.00978451987264528"
        rpy="0 0 0" />
      <mass
        value="0.0683946424473071" />
      <inertia
        ixx="6.81943433013457E-05"
        ixy="4.90870882610807E-06"
        ixz="-2.53787320186276E-08"
        iyy="5.51533096946525E-05"
        iyz="-2.19285375059936E-08"
        izz="4.64681443173627E-05" />
    </inertial>
    <visual>
      <origin
        xyz="0 0 0"
        rpy="0 0 0" />
      <geometry>
        <mesh
          filename="/home/dika/projects/AthleticRobot/robot/robot_esr_v2/meshes/left_arm_pitch_1.STL" />
      </geometry>
      <material
        name="">
        <color
          rgba="0.792156862745098 0.819607843137255 0.933333333333333 1" />
      </material>
    </visual>
    <collision>
      <origin
        xyz="0 0 0"
        rpy="0 0 0" />
      <geometry>
        <mesh
          filename="/home/dika/projects/AthleticRobot/robot/robot_esr_v2/meshes/left_arm_pitch_1.STL" />
      </geometry>
    </collision>
  </link>
  <joint
    name="left_arm_pitch_1"
    type="revolute">
    <origin
      xyz="0.116 0.1865 0"
      rpy="0 0 0" />
    <parent
      link="body_yaw" />
    <child
      link="left_arm_pitch_1" />
    <axis
      xyz="-1 0 0" />
    <limit
      lower="-3.14"
      upper="3.14"
      effort="0"
      velocity="0" />
  </joint>
  <link
    name="left_arm_roll_1">
    <inertial>
      <origin
        xyz="-8.98449423448189E-05 -0.0593378709159935 -0.0219648695125198"
        rpy="0 0 0" />
      <mass
        value="0.63999361019222" />
      <inertia
        ixx="0.000699632566014424"
        ixy="3.51428410162062E-06"
        ixz="5.73943656231475E-11"
        iyy="0.000502483362631469"
        iyz="-3.51429064120542E-06"
        izz="0.000525405260146243" />
    </inertial>
    <visual>
      <origin
        xyz="0 0 0"
        rpy="0 0 0" />
      <geometry>
        <mesh
          filename="/home/dika/projects/AthleticRobot/robot/robot_esr_v2/meshes/left_arm_roll_1.STL" />
      </geometry>
      <material
        name="">
        <color
          rgba="0.792156862745098 0.819607843137255 0.933333333333333 1" />
      </material>
    </visual>
    <collision>
      <origin
        xyz="0 0 0"
        rpy="0 0 0" />
      <geometry>
        <mesh
          filename="/home/dika/projects/AthleticRobot/robot/robot_esr_v2/meshes/left_arm_roll_1.STL" />
      </geometry>
    </collision>
  </link>
  <joint
    name="left_arm_roll_1"
    type="revolute">
    <origin
      xyz="0.096 -0.039 0.021"
      rpy="0 0 0" />
    <parent
      link="left_arm_pitch_1" />
    <child
      link="left_arm_roll_1" />
    <axis
      xyz="0 0 -1" />
    <limit
      lower="-3.14"
      upper="3.14"
      effort="0"
      velocity="0" />
  </joint>
  <link
    name="left_arm_yaw_1">
    <inertial>
      <origin
        xyz="-0.00314972637197256 -0.0551148453865819 0.000247660053044073"
        rpy="0 0 0" />
      <mass
        value="0.0464659333613769" />
      <inertia
        ixx="2.48384911458058E-05"
        ixy="-4.1090147765289E-08"
        ixz="4.78865636672483E-08"
        iyy="5.17570457355115E-05"
        iyz="1.24795287733785E-06"
        izz="4.24958513780218E-05" />
    </inertial>
    <visual>
      <origin
        xyz="0 0 0"
        rpy="0 0 0" />
      <geometry>
        <mesh
          filename="/home/dika/projects/AthleticRobot/robot/robot_esr_v2/meshes/left_arm_yaw_1.STL" />
      </geometry>
      <material
        name="">
        <color
          rgba="0.792156862745098 0.819607843137255 0.933333333333333 1" />
      </material>
    </visual>
    <collision>
      <origin
        xyz="0 0 0"
        rpy="0 0 0" />
      <geometry>
        <mesh
          filename="/home/dika/projects/AthleticRobot/robot/robot_esr_v2/meshes/left_arm_yaw_1.STL" />
      </geometry>
    </collision>
  </link>
  <joint
    name="left_arm_yaw_1"
    type="revolute">
    <origin
      xyz="5.00000000014378E-05 -0.127000000000001 -0.02355"
      rpy="0 0 0" />
    <parent
      link="left_arm_roll_1" />
    <child
      link="left_arm_yaw_1" />
    <axis
      xyz="0 1 0" />
    <limit
      lower="-3.14"
      upper="3.14"
      effort="0"
      velocity="0" />
  </joint>
  <link
    name="left_arm_pitch_3">
    <inertial>
      <origin
        xyz="-0.0228498992815529 -0.0121662464498109 0.0370621135682994"
        rpy="0 0 0" />
      <mass
        value="0.484792170050265" />
      <inertia
        ixx="0.000274229624862391"
        ixy="2.48497300759915E-06"
        ixz="-3.02651534251845E-06"
        iyy="0.000484217295409479"
        iyz="-3.33398964453887E-06"
        izz="0.000424604377814633" />
    </inertial>
    <visual>
      <origin
        xyz="0 0 0"
        rpy="0 0 0" />
      <geometry>
        <mesh
          filename="/home/dika/projects/AthleticRobot/robot/robot_esr_v2/meshes/left_arm_pitch_3.STL" />
      </geometry>
      <material
        name="">
        <color
          rgba="0.792156862745098 0.819607843137255 0.933333333333333 1" />
      </material>
    </visual>
    <collision>
      <origin
        xyz="0 0 0"
        rpy="0 0 0" />
      <geometry>
        <mesh
          filename="/home/dika/projects/AthleticRobot/robot/robot_esr_v2/meshes/left_arm_pitch_3.STL" />
      </geometry>
    </collision>
  </link>
  <joint
    name="left_arm_pitch_3"
    type="revolute">
    <origin
      xyz="0.0210000000000009 -0.0899999999999988 0.03"
      rpy="0 0 0" />
    <parent
      link="left_arm_yaw_1" />
    <child
      link="left_arm_pitch_3" />
    <axis
      xyz="-1 0 0" />
    <limit
      lower="-1.57"
      upper="1.57"
      effort="0"
      velocity="0" />
  </joint>
  <link
    name="left_arm_pitch_5">
    <inertial>
      <origin
        xyz="0.0482059827964404 -2.90245078804485E-08 0.066945329003649"
        rpy="0 0 0" />
      <mass
        value="0.156306500434488" />
      <inertia
        ixx="5.38088213797229E-05"
        ixy="-1.57189932462597E-10"
        ixz="-3.79661074209762E-06"
        iyy="0.000130632668757521"
        iyz="-9.18065276032658E-11"
        izz="0.000101199936779534" />
    </inertial>
    <visual>
      <origin
        xyz="0 0 0"
        rpy="0 0 0" />
      <geometry>
        <mesh
          filename="/home/dika/projects/AthleticRobot/robot/robot_esr_v2/meshes/left_arm_pitch_5.STL" />
      </geometry>
      <material
        name="">
        <color
          rgba="0.894117647058823 0.894117647058823 0.894117647058823 1" />
      </material>
    </visual>
    <collision>
      <origin
        xyz="0 0 0"
        rpy="0 0 0" />
      <geometry>
        <mesh
          filename="/home/dika/projects/AthleticRobot/robot/robot_esr_v2/meshes/left_arm_pitch_5.STL" />
      </geometry>
    </collision>
  </link>
  <joint
    name="left_arm_pitch_5"
    type="revolute">
    <origin
      xyz="-0.0719999999999973 -0.0300000000000009 0.107999999999998"
      rpy="0 0 0" />
    <parent
      link="left_arm_pitch_3" />
    <child
      link="left_arm_pitch_5" />
    <axis
      xyz="1 0 0" />
    <limit
      lower="-1.57"
      upper="1.57"
      effort="0"
      velocity="0" />
  </joint>
  <link
    name="left_thumb_1">
    <inertial>
      <origin
        xyz="0.0113978149358132 0.00250004948856664 -0.00145810284227833"
        rpy="0 0 0" />
      <mass
        value="0.00454617147713202" />
      <inertia
        ixx="2.00743521153476E-07"
        ixy="-2.51848874877249E-13"
        ixz="-1.50607364750756E-08"
        iyy="1.84548715488293E-07"
        iyz="-3.64133700759514E-12"
        izz="2.07595104536583E-07" />
    </inertial>
    <visual>
      <origin
        xyz="0 0 0"
        rpy="0 0 0" />
      <geometry>
        <mesh
          filename="/home/dika/projects/AthleticRobot/robot/robot_esr_v2/meshes/left_thumb_1.STL" />
      </geometry>
      <material
        name="">
        <color
          rgba="0.749019607843137 0.749019607843137 0.749019607843137 1" />
      </material>
    </visual>
    <collision>
      <origin
        xyz="0 0 0"
        rpy="0 0 0" />
      <geometry>
        <mesh
          filename="/home/dika/projects/AthleticRobot/robot/robot_esr_v2/meshes/left_thumb_1.STL" />
      </geometry>
    </collision>
  </link>
  <joint
    name="left_thumb_1"
    type="revolute">
    <origin
      xyz="0.107503962290575 -0.000182112936898127 0.0907002793513438"
      rpy="-1.5707963267949 -0.463647609000817 0" />
    <parent
      link="left_arm_pitch_5" />
    <child
      link="left_thumb_1" />
    <axis
      xyz="0 1 0" />
    <limit
      lower="-1.57"
      upper="1.57"
      effort="0"
      velocity="0" />
  </joint>
  <link
    name="left_thumb_3">
    <inertial>
      <origin
        xyz="0.0139587922061101 0.00249991385044582 -0.000755139885085521"
        rpy="0 0 0" />
      <mass
        value="0.00673401459589844" />
      <inertia
        ixx="2.83803162312751E-07"
        ixy="1.23437441738459E-12"
        ixz="-5.25654983167697E-08"
        iyy="5.06376773303972E-07"
        iyz="1.15098430141773E-11"
        izz="5.30107931771695E-07" />
    </inertial>
    <visual>
      <origin
        xyz="0 0 0"
        rpy="0 0 0" />
      <geometry>
        <mesh
          filename="/home/dika/projects/AthleticRobot/robot/robot_esr_v2/meshes/left_thumb_3.STL" />
      </geometry>
      <material
        name="">
        <color
          rgba="0.749019607843137 0.749019607843137 0.749019607843137 1" />
      </material>
    </visual>
    <collision>
      <origin
        xyz="0 0 0"
        rpy="0 0 0" />
      <geometry>
        <mesh
          filename="/home/dika/projects/AthleticRobot/robot/robot_esr_v2/meshes/left_thumb_3.STL" />
      </geometry>
    </collision>
  </link>
  <joint
    name="left_thumb_3"
    type="revolute">
    <origin
      xyz="0.024 0 0"
      rpy="0 0 0" />
    <parent
      link="left_thumb_1" />
    <child
      link="left_thumb_3" />
    <axis
      xyz="0 -1 0" />
    <limit
      lower="-1.57"
      upper="1.57"
      effort="0"
      velocity="0" />
  </joint>
  <link
    name="left_finger_1">
    <inertial>
      <origin
        xyz="0.0210005072859824 -0.00400017377724532 0.00133245854125119"
        rpy="0 0 0" />
      <mass
        value="0.0353312025142188" />
      <inertia
        ixx="3.41571420193748E-06"
        ixy="4.14316267511572E-11"
        ixz="2.22275655998046E-07"
        iyy="3.6485420216146E-06"
        iyz="1.23052264658773E-10"
        izz="5.51776940396891E-06" />
    </inertial>
    <visual>
      <origin
        xyz="0 0 0"
        rpy="0 0 0" />
      <geometry>
        <mesh
          filename="/home/dika/projects/AthleticRobot/robot/robot_esr_v2/meshes/left_finger_1.STL" />
      </geometry>
      <material
        name="">
        <color
          rgba="0.749019607843137 0.749019607843137 0.749019607843137 1" />
      </material>
    </visual>
    <collision>
      <origin
        xyz="0 0 0"
        rpy="0 0 0" />
      <geometry>
        <mesh
          filename="/home/dika/projects/AthleticRobot/robot/robot_esr_v2/meshes/left_finger_1.STL" />
      </geometry>
    </collision>
  </link>
  <joint
    name="left_finger_1"
    type="revolute">
    <origin
      xyz="0.0409999999999965 0 0.111248350851725"
      rpy="1.57079632679489 -1.5707963267949 0" />
    <parent
      link="left_arm_pitch_5" />
    <child
      link="left_finger_1" />
    <axis
      xyz="0 -1 0" />
    <limit
      lower="-1.57"
      upper="1.57"
      effort="0"
      velocity="0" />
  </joint>
  <link
    name="left_finger_3">
    <inertial>
      <origin
        xyz="0.0247059022842294 -0.00408196880846209 0.000316274090357574"
        rpy="0 0 0" />
      <mass
        value="0.0496222031017559" />
      <inertia
        ixx="4.81577791864651E-06"
        ixy="4.06538724149698E-11"
        ixz="2.88326402347796E-07"
        iyy="7.89378851532628E-06"
        iyz="-9.82124654179956E-11"
        izz="1.04187510323155E-05" />
    </inertial>
    <visual>
      <origin
        xyz="0 0 0"
        rpy="0 0 0" />
      <geometry>
        <mesh
          filename="/home/dika/projects/AthleticRobot/robot/robot_esr_v2/meshes/left_finger_3.STL" />
      </geometry>
      <material
        name="">
        <color
          rgba="0.749019607843137 0.749019607843137 0.749019607843137 1" />
      </material>
    </visual>
    <collision>
      <origin
        xyz="0 0 0"
        rpy="0 0 0" />
      <geometry>
        <mesh
          filename="/home/dika/projects/AthleticRobot/robot/robot_esr_v2/meshes/left_finger_3.STL" />
      </geometry>
    </collision>
  </link>
  <joint
    name="left_finger_3"
    type="revolute">
    <origin
      xyz="0.0395 0 0"
      rpy="0 0 0" />
    <parent
      link="left_finger_1" />
    <child
      link="left_finger_3" />
    <axis
      xyz="0 -1 0" />
    <limit
      lower="-1.57"
      upper="1.57"
      effort="0"
      velocity="0" />
  </joint>
  <link
    name="head_yaw">
    <inertial>
      <origin
        xyz="-0.00319061283420851 0.00851526095707716 2.8771975424456E-10"
        rpy="0 0 0" />
      <mass
        value="0.0319510463220568" />
      <inertia
        ixx="8.58129604215483E-06"
        ixy="-6.46292988270477E-09"
        ixz="2.37231245640147E-13"
        iyy="2.16127326939667E-05"
        iyz="-3.30433402286285E-15"
        izz="1.73927084023207E-05" />
    </inertial>
    <visual>
      <origin
        xyz="0 0 0"
        rpy="0 0 0" />
      <geometry>
        <mesh
          filename="/home/dika/projects/AthleticRobot/robot/robot_esr_v2/meshes/head_yaw.STL" />
      </geometry>
      <material
        name="">
        <color
          rgba="0.894117647058823 0.894117647058823 0.894117647058823 1" />
      </material>
    </visual>
    <collision>
      <origin
        xyz="0 0 0"
        rpy="0 0 0" />
      <geometry>
        <mesh
          filename="/home/dika/projects/AthleticRobot/robot/robot_esr_v2/meshes/head_yaw.STL" />
      </geometry>
    </collision>
  </link>
  <joint
    name="head_yaw"
    type="continuous">
    <origin
      xyz="0 0.2555 0"
      rpy="0 0 0" />
    <parent
      link="body_yaw" />
    <child
      link="head_yaw" />
    <axis
      xyz="0 -1 0" />
  </joint>
  <link
    name="head_pitch">
    <inertial>
      <origin
        xyz="0.0461981071720124 0.0231062677374707 0.00527965222944249"
        rpy="0 0 0" />
      <mass
        value="0.321443315879583" />
      <inertia
        ixx="0.000112608954283966"
        ixy="2.31857399941169E-09"
        ixz="-5.62882697184185E-07"
        iyy="0.000252700667911886"
        iyz="1.80241481368462E-07"
        izz="0.000211544285995708" />
    </inertial>
    <visual>
      <origin
        xyz="0 0 0"
        rpy="0 0 0" />
      <geometry>
        <mesh
          filename="/home/dika/projects/AthleticRobot/robot/robot_esr_v2/meshes/head_pitch.STL" />
      </geometry>
      <material
        name="">
        <color
          rgba="0.894117647058823 0.894117647058823 0.894117647058823 1" />
      </material>
    </visual>
    <collision>
      <origin
        xyz="0 0 0"
        rpy="0 0 0" />
      <geometry>
        <mesh
          filename="/home/dika/projects/AthleticRobot/robot/robot_esr_v2/meshes/head_pitch.STL" />
      </geometry>
    </collision>
  </link>
  <joint
    name="head_pitch"
    type="revolute">
    <origin
      xyz="-0.045 0.039 0"
      rpy="0 0 0" />
    <parent
      link="head_yaw" />
    <child
      link="head_pitch" />
    <axis
      xyz="1 0 0" />
    <limit
      lower="-1.57"
      upper="1.57"
      effort="0"
      velocity="0" />
  </joint>
</robot>
